Workbook

Sheet iOS Camera (Built-in)
A1: LOG PENGUJIAN: IOS CAMERA (BUILT-IN)
A2: No | B2: Waktu | C2: URL | D2: Label Aktual | E2: Kategori | F2: Hasil Scanner | G2: TP | H2: FP | I2: FN | J2: TN | K2: Benar? | L2: Catatan
A3: =ROW()-2 -> 1 | B3: 2026-04-06 16:39:23 | C3: https://composerprogrammer.com/introductiontocomputermusic.pdf | D3: safe | E3: Live Safe (Tech News) | F3: Aman | G3: 0 | H3: 0 | I3: 0 | J3: 1 | K3: ✅
A4: =ROW()-2 -> 2 | B4: 2026-04-06 16:39:23 | C4: https://jaso1024.com/mvidia/ | D4: safe | E4: Live Safe (Tech News) | F4: Aman | G4: 0 | H4: 0 | I4: 0 | J4: 1 | K4: ✅
A5: =ROW()-2 -> 3 | B5: 2026-04-06 16:39:23 | C5: https://github.com/siddharthvaddem/openscreen | D5: safe | E5: Live Safe (Tech News) | F5: Aman | G5: 0 | H5: 0 | I5: 0 | J5: 1 | K5: ✅
A6: =ROW()-2 -> 4 | B6: 2026-04-06 16:39:23 | C6: https://taggart-tech.com/reckoning/ | D6: safe | E6: Live Safe (Tech News) | F6: Aman | G6: 0 | H6: 0 | I6: 0 | J6: 1 | K6: ✅
A7: =ROW()-2 -> 5 | B7: 2026-04-06 16:39:24 | C7: https://jonno.nz/posts/what-if-your-browser-built-the-ui-for-you/ | D7: safe | E7: Live Safe (Tech News) | F7: Aman | G7: 0 | H7: 0 | I7: 0 | J7: 1 | K7: ✅
A8: =ROW()-2 -> 6 | B8: 2026-04-06 16:39:24 | C8: https://gist.github.com/karpathy/442a6bf555914893e9891c11519de94f | D8: safe | E8: Live Safe (Tech News) | F8: Aman | G8: 0 | H8: 0 | I8: 0 | J8: 1 | K8: ✅
A9: =ROW()-2 -> 7 | B9: 2026-04-06 16:39:24 | C9: https://twitter.com/VladTheInflator/status/2039577001531768906 | D9: safe | E9: Live Safe (Tech News) | F9: Aman | G9: 0 | H9: 0 | I9: 0 | J9: 1 | K9: ✅
A10: =ROW()-2 -> 8 | B10: 2026-04-06 16:39:24 | C10: https://blog.djhaskin.com/blog/writing-lisp-is-ai-resistant-and-im-sad/ | D10: safe | E10: Live Safe (Tech News) | F10: Aman | G10: 0 | H10: 0 | I10: 0 | J10: 1 | K10: ✅
A11: =ROW()-2 -> 9 | B11: 2026-04-06 16:39:24 | C11: https://teybannerman.com/strategy/2026/03/31/how-many-microsoft-copilot-are-there.html | D11: safe | E11: Live Safe (Tech News) | F11: Aman | G11: 0 | H11: 0 | I11: 0 | J11: 1 | K11: ✅
A12: =ROW()-2 -> 10 | B12: 2026-04-06 16:39:25 | C12: https://www.phoronix.com/news/Linux-7.0-AWS-PostgreSQL-Drop | D12: safe | E12: Live Safe (Tech News) | F12: Aman | G12: 0 | H12: 0 | I12: 0 | J12: 1 | K12: ✅
A13: =ROW()-2 -> 11 | B13: 2026-04-06 16:39:25 | C13: https://www.science.org/doi/10.1126/sciadv.aef5697 | D13: safe | E13: Live Safe (Tech News) | F13: Aman | G13: 0 | H13: 0 | I13: 0 | J13: 1 | K13: ✅
A14: =ROW()-2 -> 12 | B14: 2026-04-06 16:39:25 | C14: https://github.com/KaiPereira/Overglade-Badges | D14: safe | E14: Live Safe (Tech News) | F14: Aman | G14: 0 | H14: 0 | I14: 0 | J14: 1 | K14: ✅
... A1002: =ROW()-2 -> 1000 | B1002: 2026-05-11 13:08:50 | C1002: https://facebook-team.invoice-ads-manager.com/ | D1002: phishing | E1002: Typosquatting | F1002: Aman | G1002: 0 | H1002: 0 | I1002: 1 | J1002: 0 | K1002: ❌

Sheet Samsung Camera (Built-in)
A1: LOG PENGUJIAN: SAMSUNG CAMERA (BUILT-IN)
A2: No | B2: Waktu | C2: URL | D2: Label Aktual | E2: Kategori | F2: Hasil Scanner | G2: TP | H2: FP | I2: FN | J2: TN | K2: Benar? | L2: Catatan
A3: =ROW()-2 -> 1 | B3: 2026-04-07 18:01:42 | C3: https://www.science.org/content/blog-post/ah-peptides-where-begin | D3: safe | E3: Live Safe (Tech News) | F3: Aman | G3: 0 | H3: 0 | I3: 0 | J3: 1 | K3: ✅
A4: =ROW()-2 -> 2 | B4: 2026-04-07 18:01:55 | C4: https://krebsonsecurity.com/2026/04/germany-doxes-unkn-head-of-ru-ransomware-gangs-revil-gandcrab/ | D4: safe | E4: Live Safe (Tech News) | F4: Aman | G4: 0 | H4: 0 | I4: 0 | J4: 1 | K4: ✅
A5: =ROW()-2 -> 3 | B5: 2026-04-07 18:02:00 | C5: https://www.govauctions.app/ | D5: safe | E5: Live Safe (Tech News) | F5: Aman | G5: 0 | H5: 0 | I5: 0 | J5: 1 | K5: ✅
A6: =ROW()-2 -> 4 | B6: 2026-04-07 18:02:14 | C6: https://adashape.com | D6: safe | E6: Live Safe (Tech News) | F6: Aman | G6: 0 | H6: 0 | I6: 0 | J6: 1 | K6: ✅
A7: =ROW()-2 -> 5 | B7: 2026-04-07 18:02:24 | C7: https://belief.horse/notes/what-being-ripped-off-taught-me/ | D7: safe | E7: Live Safe (Tech News) | F7: Aman | G7: 0 | H7: 0 | I7: 0 | J7: 1 | K7: ✅
A8: =ROW()-2 -> 6 | B8: 2026-04-07 18:02:32 | C8: https://www.showbiz411.com/2026/04/05/itunes-takeover-by-fake-ai-singer-eddie-dalton-now-occupies-eleven-spots-on-chart-despite-not-being-human-or-real-exclusive | D8: safe | E8: Live Safe (Tech News) | F8: Aman | G8: 0 | H8: 0 | I8: 0 | J8: 1 | K8: ✅
A9: =ROW()-2 -> 7 | B9: 2026-04-07 18:02:40 | C9: https://www.stephendiehl.com/posts/no_antimimetics/ | D9: safe | E9: Live Safe (Tech News) | F9: Aman | G9: 0 | H9: 0 | I9: 0 | J9: 1 | K9: ✅
A10: =ROW()-2 -> 8 | B10: 2026-04-07 18:02:45 | C10: https://github.com/roscopeco/anos | D10: safe | E10: Live Safe (Tech News) | F10: Aman | G10: 0 | H10: 0 | I10: 0 | J10: 1 | K10: ✅
A11: =ROW()-2 -> 9 | B11: 2026-04-07 18:02:55 | C11: https://www.anthropic.com/news/google-broadcom-partnership-compute | D11: safe | E11: Live Safe (Tech News) | F11: Aman | G11: 0 | H11: 0 | I11: 0 | J11: 1 | K11: ✅
A12: =ROW()-2 -> 10 | B12: 2026-04-07 18:03:24 | C12: https://www.terrygodier.com/the-last-quiet-thing | D12: safe | E12: Live Safe (Tech News) | F12: Phishing | G12: 0 | H12: 1 | I12: 0 | J12: 0 | K12: ❌
A13: =ROW()-2 -> 11 | B13: 2026-04-07 18:03:29 | C13: https://github.com/Netflix/void-model | D13: safe | E13: Live Safe (Tech News) | F13: Aman | G13: 0 | H13: 0 | I13: 0 | J13: 1 | K13: ✅
A14: =ROW()-2 -> 12 | B14: 2026-04-07 18:03:34 | C14: https://github.com/kitfunso/hippo-memory | D14: safe | E14: Live Safe (Tech News) | F14: Aman | G14: 0 | H14: 0 | I14: 0 | J14: 1 | K14: ✅
... A190: =ROW()-2 -> 188 | B190: 2026-04-07 18:41:19 | C190: https://prtuge.com/ | D190: phishing | E190: Typosquatting | F190: Phishing | G190: 1 | H190: 0 | I190: 0 | J190: 0 | K190: ✅
A191: =ROW()-2 -> 189 | B191: 46119.362 | C191: https://trkloge23.serv00.net/dkb/login.php | D191: phishing | E191: Credential Harvesting | F191: Phishing | G191: 1 | H191: 0 | I191: 0 | J191: 0 | K191: ✅
A192: =ROW()-2 -> 190 | B192: 2026-04-07 08:40:54 | C192: https://trkloge23.serv00.net/dkb/login.php | D192: phishing | E192: Credential Harvesting | F192: Phishing | G192: 1 | H192: 0 | I192: 0 | J192: 0 | K192: ✅
A193: =ROW()-2 -> 191 | B193: 2026-04-07 08:41:04 | C193: https://trkloge23.serv00.net/dkb/login.php | D193: phishing | E193: Credential Harvesting | F193: Phishing | G193: 1 | H193: 0 | I193: 0 | J193: 0 | K193: ✅
A194: =ROW()-2 -> 192 | B194: 2026-04-07 17:45:30 | C194: https://ledger-com-start.vercel.app/ | D194: phishing | E194: Typosquatting | F194: Aman | G194: 0 | H194: 0 | I194: 1 | J194: 0 | K194: ❌
A195: =ROW()-2 -> 193 | B195: 2026-04-07 17:45:36 | C195: https://himani2484.github.io/amazon_clone/ | D195: phishing | E195: Typosquatting | F195: Aman | G195: 0 | H195: 0 | I195: 1 | J195: 0 | K195: ❌
A196: =ROW()-2 -> 194 | B196: 2026-04-07 17:45:51 | C196: https://invoicenotices.com/s/63BZGFSVBWSFCDX7Y9/584dd8/90eab167-7429-489f-99f6-ce86e8d0d81a | D196: phishing | E196: Typosquatting | F196: Aman | G196: 0 | H196: 0 | I196: 1 | J196: 0 | K196: ❌
A197: =ROW()-2 -> 195 | B197: 2026-04-07 17:45:58 | C197: https://135461223.site/sv/458/e44f214b-73f9-45e0-8ebb-2f43d17fd104/722221/x | D197: phishing | E197: Suspicious TLDs | F197: Aman | G197: 0 | H197: 0 | I197: 1 | J197: 0 | K197: ❌
A198: =ROW()-2 -> 196 | B198: 2026-04-07 17:46:07 | C198: https://roblox.com.ge/games/14751762996/JAGA-JAGA-ROBLOCKS-QUEEN?privateServerLinkCode=90159241212172745697009764022288 | D198: phishing | E198: Typosquatting | F198: Aman | G198: 0 | H198: 0 | I198: 1 | J198: 0 | K198: ❌
A199: =ROW()-2 -> 197 | B199: 2026-04-07 17:46:23 | C199: https://www.robiox.com.py/users/372564895763/profile | D199: phishing | E199: Typosquatting | F199: Aman | G199: 0 | H199: 0 | I199: 1 | J199: 0 | K199: ❌
A200: =ROW()-2 -> 198 | B200: 2026-04-07 17:46:32 | C200: https://hero-shanon.github.io/netflix-clone/ | D200: phishing | E200: Typosquatting | F200: Aman | G200: 0 | H200: 0 | I200: 1 | J200: 0 | K200: ❌
A201: =ROW()-2 -> 199 | B201: 2026-04-07 17:46:45 | C201: https://www.roblox.com.bn/games/131623223084840/Escape-Tsunami-For-Brainrots?privateServerLinkCode=80674271570847510930111301270272 | D201: phishing | E201: Typosquatting | F201: Aman | G201: 0 | H201: 0 | I201: 1 | J201: 0 | K201: ❌
A202: =ROW()-2 -> 200 | B202: 2026-04-07 17:46:55 | C202: https://roblox.com.ge/games/131378148336503/MODIF-x-EVENT-UPDATE-Drag-Drive-Simulator?privateServerLinkCode=14466708996407142075998321163891 | D202: phishing | E202: Credential Harvesting | F202: Aman | G202: 0 | H202: 0 | I202: 1 | J202: 0 | K202: ❌
A203: =ROW()-2 -> 201 | B203: 2026-04-07 18:01:42 | C203: https://www.science.org/content/blog-post/ah-peptides-where-begin | D203: safe | E203: Live Safe (Tech News) | F203: Aman | G203: 0 | H203: 0 | I203: 0 | J203: 1 | K203: ✅
... A1002: =ROW()-2 -> 1000 | B1002: 2026-05-11 17:51:06 | C1002: https://microsoft.authorised-support.com/new-account/EOzAFbYj1bjLmgufSIlKJJR9Kpvsy5kc3UkY=3Ag==3XlpQQVxAXFVHbF9cVFpdbERaR1tsQ1JAQERcQVc=/6Xx5KG1mKRNjeU3rSnC8diFTM7R4V1de | D1002: phishing | E1002: Credential Harvesting | F1002: Aman | G1002: 0 | H1002: 0 | I1002: 1 | J1002: 0 | K1002: ❌

Sheet Redmi Camera (Built-in)
A1: LOG PENGUJIAN: REDMI CAMERA (BUILT-IN)
A2: No | B2: Waktu | C2: URL | D2: Label Aktual | E2: Kategori | F2: Hasil Scanner | G2: TP | H2: FP | I2: FN | J2: TN | K2: Benar? | L2: Catatan
A3: =ROW()-2 -> 1 | B3: 2026-04-06 10:48:03 | C3: https://composerprogrammer.com/introductiontocomputermusic.pdf | D3: safe | E3: Live Safe (Tech News) | F3: Aman | G3: 0 | H3: 0 | I3: 0 | J3: 1 | K3: ✅
A4: =ROW()-2 -> 2 | B4: 2026-04-06 10:48:26 | C4: https://jaso1024.com/mvidia/ | D4: safe | E4: Live Safe (Tech News) | F4: Aman | G4: 0 | H4: 0 | I4: 0 | J4: 1 | K4: ✅
A5: =ROW()-2 -> 3 | B5: 2026-04-06 10:48:50 | C5: https://github.com/siddharthvaddem/openscreen | D5: safe | E5: Live Safe (Tech News) | F5: Aman | G5: 0 | H5: 0 | I5: 0 | J5: 1 | K5: ✅
A6: =ROW()-2 -> 4 | B6: 2026-04-06 10:49:04 | C6: https://taggart-tech.com/reckoning/ | D6: safe | E6: Live Safe (Tech News) | F6: Aman | G6: 0 | H6: 0 | I6: 0 | J6: 1 | K6: ✅
A7: =ROW()-2 -> 5 | B7: 2026-04-06 10:49:21 | C7: https://jonno.nz/posts/what-if-your-browser-built-the-ui-for-you/ | D7: safe | E7: Live Safe (Tech News) | F7: Aman | G7: 0 | H7: 0 | I7: 0 | J7: 1 | K7: ✅
A8: =ROW()-2 -> 6 | B8: 2026-04-06 10:49:39 | C8: https://gist.github.com/karpathy/442a6bf555914893e9891c11519de94f | D8: safe | E8: Live Safe (Tech News) | F8: Aman | G8: 0 | H8: 0 | I8: 0 | J8: 1 | K8: ✅
A9: =ROW()-2 -> 7 | B9: 2026-04-06 10:49:55 | C9: https://twitter.com/VladTheInflator/status/2039577001531768906 | D9: safe | E9: Live Safe (Tech News) | F9: Aman | G9: 0 | H9: 0 | I9: 0 | J9: 1 | K9: ✅
A10: =ROW()-2 -> 8 | B10: 2026-04-06 10:50:09 | C10: https://blog.djhaskin.com/blog/writing-lisp-is-ai-resistant-and-im-sad/ | D10: safe | E10: Live Safe (Tech News) | F10: Aman | G10: 0 | H10: 0 | I10: 0 | J10: 1 | K10: ✅
A11: =ROW()-2 -> 9 | B11: 2026-04-06 10:50:22 | C11: https://teybannerman.com/strategy/2026/03/31/how-many-microsoft-copilot-are-there.html | D11: safe | E11: Live Safe (Tech News) | F11: Aman | G11: 0 | H11: 0 | I11: 0 | J11: 1 | K11: ✅
A12: =ROW()-2 -> 10 | B12: 2026-04-06 10:50:35 | C12: https://www.phoronix.com/news/Linux-7.0-AWS-PostgreSQL-Drop | D12: safe | E12: Live Safe (Tech News) | F12: Aman | G12: 0 | H12: 0 | I12: 0 | J12: 1 | K12: ✅
A13: =ROW()-2 -> 11 | B13: 2026-04-06 10:50:50 | C13: https://www.science.org/doi/10.1126/sciadv.aef5697 | D13: safe | E13: Live Safe (Tech News) | F13: Aman | G13: 0 | H13: 0 | I13: 0 | J13: 1 | K13: ✅
A14: =ROW()-2 -> 12 | B14: 2026-04-06 10:51:04 | C14: https://github.com/KaiPereira/Overglade-Badges | D14: safe | E14: Live Safe (Tech News) | F14: Aman | G14: 0 | H14: 0 | I14: 0 | J14: 1 | K14: ✅
... A1002: =ROW()-2 -> 1000 | B1002: 2026-05-11 22:10:21 | C1002: https://microsoft.authorised-support.com/new-account/EOzAFbYj1bjLmgufSIlKJJR9Kpvsy5kc3UkY=3Ag==3XlpQQVxAXFVHbF9cVFpdbERaR1tsQ1JAQERcQVc=/6Xx5KG1mKRNjeU3rSnC8diFTM7R4V1de | D1002: phishing | E1002: Credential Harvesting | F1002: Phishing | G1002: 1 | H1002: 0 | I1002: 0 | J1002: 0 | K1002: ✅

Sheet Google Lens
A1: LOG PENGUJIAN: GOOGLE LENS
A2: No | B2: Waktu | C2: URL | D2: Label Aktual | E2: Kategori | F2: Hasil Scanner | G2: TP | H2: FP | I2: FN | J2: TN | K2: Benar? | L2: Catatan
A3: =ROW()-2 -> 1 | B3: 2026-04-07 07:59:57 | C3: https://composerprogrammer.com/introductiontocomputermusic.pdf | D3: safe | E3: Live Safe (Tech News) | F3: Aman | G3: 0 | H3: 0 | I3: 0 | J3: 1 | K3: ✅
A4: =ROW()-2 -> 2 | B4: 2026-04-07 08:00:15 | C4: https://jaso1024.com/mvidia/ | D4: safe | E4: Live Safe (Tech News) | F4: Aman | G4: 0 | H4: 0 | I4: 0 | J4: 1 | K4: ✅
A5: =ROW()-2 -> 3 | B5: 2026-04-07 08:00:39 | C5: https://github.com/siddharthvaddem/openscreen | D5: safe | E5: Live Safe (Tech News) | F5: Aman | G5: 0 | H5: 0 | I5: 0 | J5: 1 | K5: ✅
A6: =ROW()-2 -> 4 | B6: 2026-04-07 08:00:52 | C6: https://taggart-tech.com/reckoning/ | D6: safe | E6: Live Safe (Tech News) | F6: Aman | G6: 0 | H6: 0 | I6: 0 | J6: 1 | K6: ✅
A7: =ROW()-2 -> 5 | B7: 2026-04-07 08:01:01 | C7: https://jonno.nz/posts/what-if-your-browser-built-the-ui-for-you/ | D7: safe | E7: Live Safe (Tech News) | F7: Aman | G7: 0 | H7: 0 | I7: 0 | J7: 1 | K7: ✅
A8: =ROW()-2 -> 6 | B8: 2026-04-07 08:01:14 | C8: https://gist.github.com/karpathy/442a6bf555914893e9891c11519de94f | D8: safe | E8: Live Safe (Tech News) | F8: Aman | G8: 0 | H8: 0 | I8: 0 | J8: 1 | K8: ✅
A9: =ROW()-2 -> 7 | B9: 2026-04-07 08:01:37 | C9: https://twitter.com/VladTheInflator/status/2039577001531768906 | D9: safe | E9: Live Safe (Tech News) | F9: Aman | G9: 0 | H9: 0 | I9: 0 | J9: 1 | K9: ✅
A10: =ROW()-2 -> 8 | B10: 2026-04-07 08:01:45 | C10: https://blog.djhaskin.com/blog/writing-lisp-is-ai-resistant-and-im-sad/ | D10: safe | E10: Live Safe (Tech News) | F10: Aman | G10: 0 | H10: 0 | I10: 0 | J10: 1 | K10: ✅
A11: =ROW()-2 -> 9 | B11: 2026-04-07 08:01:52 | C11: https://teybannerman.com/strategy/2026/03/31/how-many-microsoft-copilot-are-there.html | D11: safe | E11: Live Safe (Tech News) | F11: Aman | G11: 0 | H11: 0 | I11: 0 | J11: 1 | K11: ✅
A12: =ROW()-2 -> 10 | B12: 2026-04-07 08:01:58 | C12: https://www.phoronix.com/news/Linux-7.0-AWS-PostgreSQL-Drop | D12: safe | E12: Live Safe (Tech News) | F12: Aman | G12: 0 | H12: 0 | I12: 0 | J12: 1 | K12: ✅
A13: =ROW()-2 -> 11 | B13: 2026-04-07 08:02:05 | C13: https://www.science.org/doi/10.1126/sciadv.aef5697 | D13: safe | E13: Live Safe (Tech News) | F13: Aman | G13: 0 | H13: 0 | I13: 0 | J13: 1 | K13: ✅
A14: =ROW()-2 -> 12 | B14: 2026-04-07 08:02:12 | C14: https://github.com/KaiPereira/Overglade-Badges | D14: safe | E14: Live Safe (Tech News) | F14: Aman | G14: 0 | H14: 0 | I14: 0 | J14: 1 | K14: ✅
... A40: =ROW()-2 -> 38 | B40: 2026-04-07 08:06:12 | C40: https://www.robiox.com.py/users/381961239698/profile | D40: phishing | E40: Typosquatting | F40: Aman | G40: 0 | H40: 0 | I40: 1 | J40: 0 | K40: ❌
A41: =ROW()-2 -> 39 | B41: 2026-04-07 08:10:18 | C41: http://p3bvt5dt5ra3gu.my.id/ | D41: phishing | E41: Mixed Content | F41: Phishing | G41: 1 | H41: 0 | I41: 0 | J41: 0 | K41: ✅ | L41: site can't be reached
A42: =ROW()-2 -> 40 | B42: 2026-04-07 08:10:38 | C42: https://trust-blockfi.webflow.io/ | D42: phishing | E42: Typosquatting | F42: Aman | G42: 0 | H42: 0 | I42: 1 | J42: 0 | K42: ❌
A43: =ROW()-2 -> 41 | B43: 2026-04-07 08:10:48 | C43: http://aktydnapyltr-idx.mmexe.my.id/ | D43: phishing | E43: Mixed Content | F43: Phishing | G43: 1 | H43: 0 | I43: 0 | J43: 0 | K43: ✅ | L43: site can't be reached
A44: =ROW()-2 -> 42 | B44: 2026-04-07 08:11:02 | C44: https://netflix-clone-mu-seven.vercel.app/ | D44: phishing | E44: Typosquatting | F44: Phishing | G44: 1 | H44: 0 | I44: 0 | J44: 0 | K44: ✅
A45: =ROW()-2 -> 43 | B45: 2026-04-07 08:11:18 | C45: http://www.netflix-clone-mu-seven.vercel.app/ | D45: phishing | E45: Mixed Content | F45: Phishing | G45: 1 | H45: 0 | I45: 0 | J45: 0 | K45: ✅
A46: =ROW()-2 -> 44 | B46: 2026-04-07 08:11:36 | C46: https://www.robiox.com.ps/games/920587237/Adopt-Me?privateServerLinkCode=41319586290522207122079569408427 | D46: phishing | E46: Typosquatting | F46: Phishing | G46: 1 | H46: 0 | I46: 0 | J46: 0 | K46: ✅ | L46: site can't be found
A47: =ROW()-2 -> 45 | B47: 2026-04-07 08:11:43 | C47: https://dpd.parcelroutepoint.cfd/com/ | D47: phishing | E47: Typosquatting | F47: Phishing | G47: 1 | H47: 0 | I47: 0 | J47: 0 | K47: ✅
A48: =ROW()-2 -> 46 | B48: 2026-04-07 08:11:48 | C48: https://dpd.parcelfollowhub.cfd/com/ | D48: phishing | E48: Typosquatting | F48: Phishing | G48: 1 | H48: 0 | I48: 0 | J48: 0 | K48: ✅
A49: =ROW()-2 -> 47 | B49: 2026-04-07 08:11:56 | C49: https://dpd.parcelroutenotice.cfd/com/ | D49: phishing | E49: Typosquatting | F49: Phishing | G49: 1 | H49: 0 | I49: 0 | J49: 0 | K49: ✅
A50: =ROW()-2 -> 48 | B50: 2026-04-07 08:11:59 | C50: https://dpd.parcelsignalpoint.cfd/com/ | D50: phishing | E50: Typosquatting | F50: Phishing | G50: 1 | H50: 0 | I50: 0 | J50: 0 | K50: ✅
A51: =ROW()-2 -> 49 | B51: 2026-04-07 08:12:03 | C51: http://bitfghurt-login.webflow.io/ | D51: phishing | E51: Mixed Content | F51: Phishing | G51: 1 | H51: 0 | I51: 0 | J51: 0 | K51: ✅
A52: =ROW()-2 -> 50 | B52: 2026-04-07 08:12:07 | C52: https://coinbase.aw-windblocker.com/ | D52: phishing | E52: Typosquatting | F52: Phishing | G52: 1 | H52: 0 | I52: 0 | J52: 0 | K52: ✅
A53: =ROW()-2 -> 51 | B53: 2026-04-07 08:12:11 | C53: https://coinbase.hrbwya.com/ | D53: phishing | E53: Typosquatting | F53: Phishing | G53: 1 | H53: 0 | I53: 0 | J53: 0 | K53: ✅
A54: =ROW()-2 -> 52 | B54: 2026-04-07 08:12:17 | C54: http://undian-whatsapp58.blogspot.com/ | D54: phishing | E54: Mixed Content | F54: Aman | G54: 0 | H54: 0 | I54: 1 | J54: 0 | K54: ❌
A55: =ROW()-2 -> 53 | B55: 2026-04-07 08:12:25 | C55: http://www.undian-whatsapp58.blogspot.com/ | D55: phishing | E55: Mixed Content | F55: Aman | G55: 0 | H55: 0 | I55: 1 | J55: 0 | K55: ❌
A56: =ROW()-2 -> 54 | B56: 2026-04-07 08:12:49 | C56: http://www.instagram-clone-sabitalizade.vercel.app/ | D56: phishing | E56: Mixed Content | F56: Phishing | G56: 1 | H56: 0 | I56: 0 | J56: 0 | K56: ✅ | L56: your connection is not private
A57: =ROW()-2 -> 55 | B57: 2026-04-07 08:13:03 | C57: http://www.mitrafreelancerjob.online/ | D57: phishing | E57: Suspicious TLDs | F57: Phishing | G57: 1 | H57: 0 | I57: 0 | J57: 0 | K57: ✅
A58: =ROW()-2 -> 56 | B58: 2026-04-07 08:13:07 | C58: https://dpd.parcelstakvl.bond/uk/ | D58: phishing | E58: Typosquatting | F58: Phishing | G58: 1 | H58: 0 | I58: 0 | J58: 0 | K58: ✅
A59: =ROW()-2 -> 57 | B59: 2026-04-07 08:13:11 | C59: https://dpd.parcelstakzu.bond/uk/ | D59: phishing | E59: Typosquatting | F59: Phishing | G59: 1 | H59: 0 | I59: 0 | J59: 0 | K59: ✅
A60: =ROW()-2 -> 58 | B60: 2026-04-07 08:13:15 | C60: https://dpd.parcelstakzy.bond/uk/ | D60: phishing | E60: Typosquatting | F60: Phishing | G60: 1 | H60: 0 | I60: 0 | J60: 0 | K60: ✅
A61: =ROW()-2 -> 59 | B61: 2026-04-07 08:13:20 | C61: https://dpd.parcelstakzp.bond/uk/ | D61: phishing | E61: Typosquatting | F61: Phishing | G61: 1 | H61: 0 | I61: 0 | J61: 0 | K61: ✅
A62: =ROW()-2 -> 60 | B62: 2026-04-07 08:13:23 | C62: https://dpd.tracess-pep.icu/com/ | D62: phishing | E62: Suspicious TLDs | F62: Phishing | G62: 1 | H62: 0 | I62: 0 | J62: 0 | K62: ✅
A63: =ROW()-2 -> 61 | B63: 2026-04-07 08:13:28 | C63: http://netflix-clone-alpha-nine.vercel.app/ | D63: phishing | E63: Mixed Content | F63: Phishing | G63: 1 | H63: 0 | I63: 0 | J63: 0 | K63: ✅
A64: =ROW()-2 -> 62 | B64: 2026-04-07 08:13:34 | C64: https://ntflx-reabonnieren.com/net/update.php | D64: phishing | E64: Credential Harvesting | F64: Phishing | G64: 1 | H64: 0 | I64: 0 | J64: 0 | K64: ✅
A65: =ROW()-2 -> 63 | B65: 2026-04-07 08:13:39 | C65: http://www.70774.xyz/ | D65: phishing | E65: Suspicious TLDs | F65: Phishing | G65: 1 | H65: 0 | I65: 0 | J65: 0 | K65: ✅
...

Sheet Safe QR Code Reader
A1: LOG PENGUJIAN: Safe QR Code Reader
A2: No | B2: Waktu | C2: URL | D2: Label Aktual | E2: Kategori | F2: Hasil Scanner | G2: TP | H2: FP | I2: FN | J2: TN | K2: Benar? | L2: Catatan
A3: =ROW()-2 -> 1 | B3: 2026-04-07 17:04:57 | C3: https://composerprogrammer.com/introductiontocomputermusic.pdf | D3: safe | E3: Live Safe (Tech News) | F3: Phishing | G3: 0 | H3: 1 | I3: 0 | J3: 0 | K3: ❌
A4: =ROW()-2 -> 2 | B4: 2026-04-07 17:05:03 | C4: https://jaso1024.com/mvidia/ | D4: safe | E4: Live Safe (Tech News) | F4: Phishing | G4: 0 | H4: 1 | I4: 0 | J4: 0 | K4: ❌
A5: =ROW()-2 -> 3 | B5: 2026-04-07 17:05:11 | C5: https://github.com/siddharthvaddem/openscreen | D5: safe | E5: Live Safe (Tech News) | F5: Aman | G5: 0 | H5: 0 | I5: 0 | J5: 1 | K5: ✅
A6: =ROW()-2 -> 4 | B6: 2026-04-07 17:05:14 | C6: https://taggart-tech.com/reckoning/ | D6: safe | E6: Live Safe (Tech News) | F6: Aman | G6: 0 | H6: 0 | I6: 0 | J6: 1 | K6: ✅
A7: =ROW()-2 -> 5 | B7: 2026-04-07 17:05:55 | C7: https://jonno.nz/posts/what-if-your-browser-built-the-ui-for-you/ | D7: safe | E7: Live Safe (Tech News) | F7: Phishing | G7: 0 | H7: 1 | I7: 0 | J7: 0 | K7: ❌
A8: =ROW()-2 -> 6 | B8: 2026-04-07 17:06:00 | C8: https://gist.github.com/karpathy/442a6bf555914893e9891c11519de94f | D8: safe | E8: Live Safe (Tech News) | F8: Aman | G8: 0 | H8: 0 | I8: 0 | J8: 1 | K8: ✅
A9: =ROW()-2 -> 7 | B9: 2026-04-07 17:06:06 | C9: https://twitter.com/VladTheInflator/status/2039577001531768906 | D9: safe | E9: Live Safe (Tech News) | F9: Aman | G9: 0 | H9: 0 | I9: 0 | J9: 1 | K9: ✅
A10: =ROW()-2 -> 8 | B10: 2026-04-07 17:06:15 | C10: https://blog.djhaskin.com/blog/writing-lisp-is-ai-resistant-and-im-sad/ | D10: safe | E10: Live Safe (Tech News) | F10: Phishing | G10: 0 | H10: 1 | I10: 0 | J10: 0 | K10: ❌
A11: =ROW()-2 -> 9 | B11: 2026-04-07 17:06:19 | C11: https://teybannerman.com/strategy/2026/03/31/how-many-microsoft-copilot-are-there.html | D11: safe | E11: Live Safe (Tech News) | F11: Phishing | G11: 0 | H11: 1 | I11: 0 | J11: 0 | K11: ❌
A12: =ROW()-2 -> 10 | B12: 2026-04-07 17:06:24 | C12: https://www.phoronix.com/news/Linux-7.0-AWS-PostgreSQL-Drop | D12: safe | E12: Live Safe (Tech News) | F12: Aman | G12: 0 | H12: 0 | I12: 0 | J12: 1 | K12: ✅
A13: =ROW()-2 -> 11 | B13: 2026-04-07 17:06:28 | C13: https://www.science.org/doi/10.1126/sciadv.aef5697 | D13: safe | E13: Live Safe (Tech News) | F13: Aman | G13: 0 | H13: 0 | I13: 0 | J13: 1 | K13: ✅
A14: =ROW()-2 -> 12 | B14: 2026-04-07 17:06:32 | C14: https://github.com/KaiPereira/Overglade-Badges | D14: safe | E14: Live Safe (Tech News) | F14: Aman | G14: 0 | H14: 0 | I14: 0 | J14: 1 | K14: ✅
... A129: =ROW()-2 -> 127 | B129: 2026-04-07 17:15:32 | C129: https://bridge-hub.wixstudio.com/en-us | D129: phishing | E129: Typosquatting | F129: Phishing | G129: 1 | H129: 0 | I129: 0 | J129: 0 | K129: ✅
A130: =ROW()-2 -> 128 | B130: 2026-04-07 17:16:04 | C130: https://netflix-clone-azure-ten.vercel.app/ | D130: phishing | E130: Typosquatting | F130: Phishing | G130: 1 | H130: 0 | I130: 0 | J130: 0 | K130: ✅ | L130: unverified1
A131: =ROW()-2 -> 129 | B131: 2026-04-07 17:16:10 | C131: https://www.robiox.com.py/users/301352583815/profile | D131: phishing | E131: Typosquatting | F131: Phishing | G131: 1 | H131: 0 | I131: 0 | J131: 0 | K131: ✅ | L131: 1
A132: =ROW()-2 -> 130 | B132: 2026-04-07 17:16:13 | C132: https://linkurl.pk/HXfeb-Ur | D132: phishing | E132: Typosquatting | F132: Phishing | G132: 1 | H132: 0 | I132: 0 | J132: 0 | K132: ✅ | L132: 1
A133: =ROW()-2 -> 131 | B133: 2026-04-07 17:16:18 | C133: https://roblox.com.py/communities/7018013091/ | D133: phishing | E133: Typosquatting | F133: Phishing | G133: 1 | H133: 0 | I133: 0 | J133: 0 | K133: ✅ | L133: 1
A134: =ROW()-2 -> 132 | B134: 2026-04-07 17:16:24 | C134: http://www.is.gd/UfYiba/ | D134: phishing | E134: URL Shorteners | F134: Phishing | G134: 1 | H134: 0 | I134: 0 | J134: 0 | K134: ✅ | L134: 1
A135: =ROW()-2 -> 133 | B135: 2026-04-07 17:16:28 | C135: https://roblox.com.py/users/2159431803/profile | D135: phishing | E135: Typosquatting | F135: Phishing | G135: 1 | H135: 0 | I135: 0 | J135: 0 | K135: ✅ | L135: 1
A136: =ROW()-2 -> 134 | B136: 2026-04-07 17:16:32 | C136: https://365756zxd.com/index_m.html | D136: phishing | E136: Typosquatting | F136: Phishing | G136: 1 | H136: 0 | I136: 0 | J136: 0 | K136: ✅ | L136: 1
A137: =ROW()-2 -> 135 | B137: 2026-04-07 17:17:05 | C137: https://roblox.com.py/communities/6725198347/ | D137: phishing | E137: Typosquatting | F137: Aman | G137: 0 | H137: 0 | I137: 1 | J137: 0 | K137: ❌ | L137: 2
A138: =ROW()-2 -> 136 | B138: 2026-04-07 17:17:10 | C138: https://instagram-home-page-clone.vercel.app/ | D138: phishing | E138: Typosquatting | F138: Phishing | G138: 1 | H138: 0 | I138: 0 | J138: 0 | K138: ✅ | L138: 1
A139: =ROW()-2 -> 137 | B139: 2026-04-07 17:17:16 | C139: https://instalanding.vercel.app/ | D139: phishing | E139: Typosquatting | F139: Phishing | G139: 1 | H139: 0 | I139: 0 | J139: 0 | K139: ✅ | L139: 1
A140: =ROW()-2 -> 138 | B140: 2026-04-07 17:17:20 | C140: https://vedavikasd.github.io/Amazon-Javascript-Project/ | D140: phishing | E140: Typosquatting | F140: Phishing | G140: 1 | H140: 0 | I140: 0 | J140: 0 | K140: ✅ | L140: 1
A141: =ROW()-2 -> 139 | B141: 2026-04-07 17:17:24 | C141: https://rbxrewards.roblox-635.workers.dev/ | D141: phishing | E141: Typosquatting | F141: Phishing | G141: 1 | H141: 0 | I141: 0 | J141: 0 | K141: ✅ | L141: 1
... A152: =ROW()-2 -> 150 | B152: 2026-04-07 17:20:48 | C152: https://netflix-clone-coral-delta.vercel.app/ | D152: phishing | E152: Typosquatting | F152: Phishing | G152: 1 | H152: 0 | I152: 0 | J152: 0 | K152: ✅ | L152: 1
A153: =ROW()-2 -> 151 | B153: 2026-04-07 17:20:54 | C153: https://netflix-clone-coral-delta.vercel.app/ | D153: phishing | E153: Typosquatting | F153: Phishing | G153: 1 | H153: 0 | I153: 0 | J153: 0 | K153: ✅
A154: =ROW()-2 -> 152 | B154: 2026-04-07 17:21:00 | C154: https://netflix-clone-coral-delta.vercel.app/ | D154: phishing | E154: Typosquatting | F154: Phishing | G154: 1 | H154: 0 | I154: 0 | J154: 0 | K154: ✅ | L154: 1
A155: =ROW()-2 -> 153 | B155: 2026-04-07 17:21:19 | C155: https://netzero-mail-update-0f8eff.webflow.io/ | D155: phishing | E155: Credential Harvesting | F155: Phishing | G155: 1 | H155: 0 | I155: 0 | J155: 0 | K155: ✅ | L155: 1
A156: =ROW()-2 -> 154 | B156: 2026-04-07 17:21:24 | C156: https://www.netflix-clone-coral-delta.vercel.app/ | D156: phishing | E156: Typosquatting | F156: Phishing | G156: 1 | H156: 0 | I156: 0 | J156: 0 | K156: ✅ | L156: 1
A157: =ROW()-2 -> 155 | B157: 2026-04-07 17:21:28 | C157: https://nicholneelapu.github.io/Netflix_clone/ | D157: phishing | E157: Typosquatting | F157: Phishing | G157: 1 | H157: 0 | I157: 0 | J157: 0 | K157: ✅ | L157: 1
A158: =ROW()-2 -> 156 | B158: 2026-04-07 17:21:34 | C158: https://kaiser0207.github.io/HW3/ | D158: phishing | E158: Typosquatting | F158: Phishing | G158: 1 | H158: 0 | I158: 0 | J158: 0 | K158: ✅ | L158: 1
A159: =ROW()-2 -> 157 | B159: 2026-04-07 17:21:39 | C159: https://dpd.parcelvector.cfd/com | D159: phishing | E159: Typosquatting | F159: Phishing | G159: 1 | H159: 0 | I159: 0 | J159: 0 | K159: ✅ | L159: 1
A160: =ROW()-2 -> 158 | B160: 2026-04-07 17:21:41 | C160: https://dpd.parceltranscore.cfd/com | D160: phishing | E160: Typosquatting | F160: Phishing | G160: 1 | H160: 0 | I160: 0 | J160: 0 | K160: ✅ | L160: 1
A161: =ROW()-2 -> 159 | B161: 2026-04-07 17:21:44 | C161: https://dpd.parcelservicecenter.cfd/com | D161: phishing | E161: Typosquatting | F161: Phishing | G161: 1 | H161: 0 | I161: 0 | J161: 0 | K161: ✅ | L161: 1
A162: =ROW()-2 -> 160 | B162: 2026-04-07 17:21:48 | C162: https://jexi-bank.vercel.app/ | D162: phishing | E162: Typosquatting | F162: Phishing | G162: 1 | H162: 0 | I162: 0 | J162: 0 | K162: ✅ | L162: 1
A163: =ROW()-2 -> 161 | B163: 2026-04-07 17:21:51 | C163: https://swarna3108.github.io/project-3/ | D163: phishing | E163: Typosquatting | F163: Phishing | G163: 1 | H163: 0 | I163: 0 | J163: 0 | K163: ✅ | L163: 1
A164: =ROW()-2 -> 162 | B164: 2026-04-07 17:21:54 | C164: https://dpd.parcelserviceupdate.cfd/com | D164: phishing | E164: Credential Harvesting | F164: Phishing | G164: 1 | H164: 0 | I164: 0 | J164: 0 | K164: ✅ | L164: 1
...

Sheet QR Scan Shield
A1: LOG PENGUJIAN: QR SCAN SHIELD
A2: No | B2: Waktu | C2: URL | D2: Label Aktual | E2: Kategori | F2: Hasil Scanner | G2: TP | H2: FP | I2: FN | J2: TN | K2: Benar? | L2: Catatan
A3: =ROW()-2 -> 1 | B3: 2026-04-06 16:54:55 | C3: https://composerprogrammer.com/introductiontocomputermusic.pdf | D3: safe | E3: Live Safe (Tech News) | F3: Aman | G3: 0 | H3: 0 | I3: 0 | J3: 1 | K3: ✅
A4: =ROW()-2 -> 2 | B4: 2026-04-06 16:54:56 | C4: https://jaso1024.com/mvidia/ | D4: safe | E4: Live Safe (Tech News) | F4: Aman | G4: 0 | H4: 0 | I4: 0 | J4: 1 | K4: ✅
A5: =ROW()-2 -> 3 | B5: 2026-04-06 16:54:56 | C5: https://github.com/siddharthvaddem/openscreen | D5: safe | E5: Live Safe (Tech News) | F5: Aman | G5: 0 | H5: 0 | I5: 0 | J5: 1 | K5: ✅
A6: =ROW()-2 -> 4 | B6: 2026-04-06 16:54:57 | C6: https://taggart-tech.com/reckoning/ | D6: safe | E6: Live Safe (Tech News) | F6: Aman | G6: 0 | H6: 0 | I6: 0 | J6: 1 | K6: ✅
A7: =ROW()-2 -> 5 | B7: 2026-04-06 16:54:57 | C7: https://jonno.nz/posts/what-if-your-browser-built-the-ui-for-you/ | D7: safe | E7: Live Safe (Tech News) | F7: Aman | G7: 0 | H7: 0 | I7: 0 | J7: 1 | K7: ✅
A8: =ROW()-2 -> 6 | B8: 2026-04-06 16:54:57 | C8: https://gist.github.com/karpathy/442a6bf555914893e9891c11519de94f | D8: safe | E8: Live Safe (Tech News) | F8: Aman | G8: 0 | H8: 0 | I8: 0 | J8: 1 | K8: ✅
A9: =ROW()-2 -> 7 | B9: 2026-04-06 16:54:57 | C9: https://twitter.com/VladTheInflator/status/2039577001531768906 | D9: safe | E9: Live Safe (Tech News) | F9: Aman | G9: 0 | H9: 0 | I9: 0 | J9: 1 | K9: ✅
A10: =ROW()-2 -> 8 | B10: 2026-04-06 16:54:57 | C10: https://blog.djhaskin.com/blog/writing-lisp-is-ai-resistant-and-im-sad/ | D10: safe | E10: Live Safe (Tech News) | F10: Aman | G10: 0 | H10: 0 | I10: 0 | J10: 1 | K10: ✅
A11: =ROW()-2 -> 9 | B11: 2026-04-06 16:54:57 | C11: https://teybannerman.com/strategy/2026/03/31/how-many-microsoft-copilot-are-there.html | D11: safe | E11: Live Safe (Tech News) | F11: Aman | G11: 0 | H11: 0 | I11: 0 | J11: 1 | K11: ✅
A12: =ROW()-2 -> 10 | B12: 2026-04-06 16:54:58 | C12: https://www.phoronix.com/news/Linux-7.0-AWS-PostgreSQL-Drop | D12: safe | E12: Live Safe (Tech News) | F12: Aman | G12: 0 | H12: 0 | I12: 0 | J12: 1 | K12: ✅
A13: =ROW()-2 -> 11 | B13: 2026-04-06 16:54:58 | C13: https://www.science.org/doi/10.1126/sciadv.aef5697 | D13: safe | E13: Live Safe (Tech News) | F13: Aman | G13: 0 | H13: 0 | I13: 0 | J13: 1 | K13: ✅
A14: =ROW()-2 -> 12 | B14: 2026-04-06 16:54:58 | C14: https://github.com/KaiPereira/Overglade-Badges | D14: safe | E14: Live Safe (Tech News) | F14: Aman | G14: 0 | H14: 0 | I14: 0 | J14: 1 | K14: ✅
... A1002: =ROW()-2 -> 1000 | B1002: 2026-05-11 12:59:53 | C1002: https://microsoft.authorised-support.com/new-account/EOzAFbYj1bjLmgufSIlKJJR9Kpvsy5kc3UkY=3Ag==3XlpQQVxAXFVHbF9cVFpdbERaR1tsQ1JAQERcQVc=/6Xx5KG1mKRNjeU3rSnC8diFTM7R4V1de | D1002: phishing | E1002: Credential Harvesting | F1002: Aman | G1002: 0 | H1002: 0 | I1002: 1 | J1002: 0 | K1002: ❌

Sheet Ringkasan
A1: RINGKASAN PERBANDINGAN SEMUA SCANNER
A2: Scanner | B2: TP | C2: FP | D2: FN | E2: TN | F2: Precision | G2: Recall | H2: F1-Score
A3: iOS Camera (Built-in) | B3: =IFERROR(SUMIF('iOS Camera (Built-in)'!D$3:D$989,"phishing",'iOS Camera (Built-in)'!G$3:G$989),0) -> 272 | C3: =IFERROR(SUMIF('iOS Camera (Built-in)'!D$3:D$989,"safe",'iOS Camera (Built-in)'!H$3:H$989),0) -> 3 | D3: =IFERROR(SUMIF('iOS Camera (Built-in)'!D$3:D$989,"phishing",'iOS Camera (Built-in)'!I$3:I$989),0) -> 566 | E3: =IFERROR(SUMIF('iOS Camera (Built-in)'!D$3:D$989,"safe",'iOS Camera (Built-in)'!J$3:J$989),0) -> 146 | F3: =IFERROR(B3/(B3+C3),0) -> 0.98909091 | G3: =IFERROR(B3/(B3+D3),0) -> 0.32458234 | H3: =IFERROR(2*F3*G3/(F3+G3),0) -> 0.48876909
A4: Samsung Camera (Built-in) | B4: =IFERROR(SUMIF('Samsung Camera (Built-in)'!D$3:D$999,"phishing",'Samsung Camera (Built-in)'!G$3:G$999),0) -> 344 | C4: =IFERROR(SUMIF('Samsung Camera (Built-in)'!D$3:D$999,"safe",'Samsung Camera (Built-in)'!H$3:H$999),0) -> 5 | D4: =IFERROR(SUMIF('Samsung Camera (Built-in)'!D$3:D$999,"phishing",'Samsung Camera (Built-in)'!I$3:I$999),0) -> 526 | E4: =IFERROR(SUMIF('Samsung Camera (Built-in)'!D$3:D$999,"safe",'Samsung Camera (Built-in)'!J$3:J$999),0) -> 122 | F4: =IFERROR(B4/(B4+C4),0) -> 0.98567335 | G4: =IFERROR(B4/(B4+D4),0) -> 0.3954023 | H4: =IFERROR(2*F4*G4/(F4+G4),0) -> 0.56439705
A5: Redmi Camera (Built-in) | B5: =IFERROR(SUMIF('Redmi Camera (Built-in)'!D$3:D$1000,"phishing",'Redmi Camera (Built-in)'!G$3:G$1000),0) -> 597 | C5: =IFERROR(SUMIF('Redmi Camera (Built-in)'!D$3:D$1000,"safe",'Redmi Camera (Built-in)'!H$3:H$1000),0) -> 4 | D5: =IFERROR(SUMIF('Redmi Camera (Built-in)'!D$3:D$1000,"phishing",'Redmi Camera (Built-in)'!I$3:I$1000),0) -> 252 | E5: =IFERROR(SUMIF('Redmi Camera (Built-in)'!D$3:D$1000,"safe",'Redmi Camera (Built-in)'!J$3:J$1000),0) -> 145 | F5: =IFERROR(B5/(B5+C5),0) -> 0.99334443 | G5: =IFERROR(B5/(B5+D5),0) -> 0.70318021 | H5: =IFERROR(2*F5*G5/(F5+G5),0) -> 0.82344828
A6: Google Lens | B6: =IFERROR(SUMIF('Google Lens'!D$3:D$994,"phishing",'Google Lens'!G$3:G$994),0) -> 607 | C6: =IFERROR(SUMIF('Google Lens'!D$3:D$994,"safe",'Google Lens'!H$3:H$994),0) -> 2 | D6: =IFERROR(SUMIF('Google Lens'!D$3:D$994,"phishing",'Google Lens'!I$3:I$994),0) -> 236 | E6: =IFERROR(SUMIF('Google Lens'!D$3:D$994,"safe",'Google Lens'!J$3:J$994),0) -> 147 | F6: =IFERROR(B6/(B6+C6),0) -> 0.99671593 | G6: =IFERROR(B6/(B6+D6),0) -> 0.72004745 | H6: =IFERROR(2*F6*G6/(F6+G6),0) -> 0.83608815
A7: Safe QR Code Reader | B7: =IFERROR(SUMIF('Safe QR Code Reader'!D$3:D$1000,"phishing",'Safe QR Code Reader'!G$3:G$1000),0) -> 753 | C7: =IFERROR(SUMIF('Safe QR Code Reader'!D$3:D$1000,"safe",'Safe QR Code Reader'!H$3:H$1000),0) -> 75 | D7: =IFERROR(SUMIF('Safe QR Code Reader'!D$3:D$1000,"phishing",'Safe QR Code Reader'!I$3:I$1000),0) -> 93 | E7: =IFERROR(SUMIF('Safe QR Code Reader'!D$3:D$1000,"safe",'Safe QR Code Reader'!J$3:J$1000),0) -> 77 | F7: =IFERROR(B7/(B7+C7),0) -> 0.90942029 | G7: =IFERROR(B7/(B7+D7),0) -> 0.89007092 | H7: =IFERROR(2*F7*G7/(F7+G7),0) -> 0.89964158
A8: QR Scan Shield | B8: =IFERROR(SUMIF('QR Scan Shield'!D$3:D$1000,"phishing",'QR Scan Shield'!G$3:G$1000),0) -> 0 | C8: =IFERROR(SUMIF('QR Scan Shield'!D$3:D$1000,"safe",'QR Scan Shield'!H$3:H$1000),0) -> 0 | D8: =IFERROR(SUMIF('QR Scan Shield'!D$3:D$1000,"phishing",'QR Scan Shield'!I$3:I$1000),0) -> 851 | E8: =IFERROR(SUMIF('QR Scan Shield'!D$3:D$1000,"safe",'QR Scan Shield'!J$3:J$1000),0) -> 147 | F8: =IFERROR(B8/(B8+C8),0) -> 0 | G8: =IFERROR(B8/(B8+D8),0) -> 0 | H8: =IFERROR(2*F8*G8/(F8+G8),0) -> 0
H11: n
