Workbook

Sheet iOS Camera (Built-in)
A1: LOG PENGUJIAN: IOS CAMERA (BUILT-IN)
A2: No | B2: Waktu | C2: URL | D2: Label Aktual | E2: Kategori | F2: Hasil Scanner | G2: TP | H2: FP | I2: FN | J2: TN | K2: Benar? | L2: Catatan

Sheet Samsung Camera (Built-in)
A1: LOG PENGUJIAN: SAMSUNG CAMERA (BUILT-IN)
A2: No | B2: Waktu | C2: URL | D2: Label Aktual | E2: Kategori | F2: Hasil Scanner | G2: TP | H2: FP | I2: FN | J2: TN | K2: Benar? | L2: Catatan

Sheet Redmi Camera (Built-in)
A1: LOG PENGUJIAN: REDMI CAMERA (BUILT-IN)
A2: No | B2: Waktu | C2: URL | D2: Label Aktual | E2: Kategori | F2: Hasil Scanner | G2: TP | H2: FP | I2: FN | J2: TN | K2: Benar? | L2: Catatan

Sheet Google Lens
A1: LOG PENGUJIAN: GOOGLE LENS
A2: No | B2: Waktu | C2: URL | D2: Label Aktual | E2: Kategori | F2: Hasil Scanner | G2: TP | H2: FP | I2: FN | J2: TN | K2: Benar? | L2: Catatan
A3: 1 | B3: 2026-04-08 03:52:47 | C3: https://ccunpacked.dev/ | D3: safe | E3: Live Safe (Tech News) | F3: Aman | G3: 0 | H3: 0 | I3: 0 | J3: 1 | K3: ✅
A4: 2 | B4: 2026-04-08 03:53:04 | C4: https://home.cern/news/news/engineering/cern-levels-new-superconducting-karts | D4: safe | E4: Live Safe (Tech News) | F4: Aman | G4: 0 | H4: 0 | I4: 0 | J4: 1 | K4: ✅
A5: 3 | B5: 2026-04-08 03:53:16 | C5: https://www.science.org/content/article/neanderthals-survived-knife-s-edge-350-000-years | D5: safe | E5: Live Safe (Tech News) | F5: Aman | G5: 0 | H5: 0 | I5: 0 | J5: 1 | K5: ✅
A6: 4 | B6: 2026-04-08 03:53:30 | C6: https://blog.calif.io/p/mad-bugs-vim-vs-emacs-vs-claude | D6: safe | E6: Live Safe (Tech News) | F6: Aman | G6: 0 | H6: 0 | I6: 0 | J6: 1 | K6: ✅
A7: 5 | B7: 2026-04-08 03:54:09 | C7: https://www.jeffgeerling.com/blog/2026/minidv-with-raspberry-pi-firewire-hat/ | D7: safe | E7: Live Safe (Tech News) | F7: Aman | G7: 0 | H7: 0 | I7: 0 | J7: 1 | K7: ✅
A8: 6 | B8: 2026-04-08 03:54:23 | C8: https://arxiv.org/abs/2602.04118 | D8: safe | E8: Live Safe (Tech News) | F8: Aman | G8: 0 | H8: 0 | I8: 0 | J8: 1 | K8: ✅
A9: 7 | B9: 2026-04-08 03:54:34 | C9: https://chrisseaton.com/truffleruby/ | D9: safe | E9: Live Safe (Tech News) | F9: Aman | G9: 0 | H9: 0 | I9: 0 | J9: 1 | K9: ✅
A10: 8 | B10: 2026-04-08 03:54:44 | C10: https://prismml.com/ | D10: safe | E10: Live Safe (Tech News) | F10: Aman | G10: 0 | H10: 0 | I10: 0 | J10: 1 | K10: ✅
A11: 9 | B11: 2026-04-08 03:54:51 | C11: https://scottlawsonbc.com/post/dot-system | D11: safe | E11: Live Safe (Tech News) | F11: Aman | G11: 0 | H11: 0 | I11: 0 | J11: 1 | K11: ✅
A12: 10 | B12: 2026-04-08 03:55:00 | C12: https://github.com/yannick-cw/korb | D12: safe | E12: Live Safe (Tech News) | F12: Aman | G12: 0 | H12: 0 | I12: 0 | J12: 1 | K12: ✅
A13: 11 | B13: 2026-04-08 03:55:15 | C13: https://ministack.org/ | D13: safe | E13: Live Safe (Tech News) | F13: Aman | G13: 0 | H13: 0 | I13: 0 | J13: 1 | K13: ✅
A14: 12 | B14: 2026-04-08 03:55:22 | C14: https://alex000kim.com/posts/2026-03-31-claude-code-source-leak/ | D14: safe | E14: Live Safe (Tech News) | F14: Aman | G14: 0 | H14: 0 | I14: 0 | J14: 1 | K14: ✅
... A32: 30 | B32: 2026-04-08 03:58:33 | C32: https://www.os2museum.com/wp/learn-something-old-every-day-part-xviii-how-does-fpu-detection-work/ | D32: safe | E32: Live Safe (Tech News) | F32: Aman | G32: 0 | H32: 0 | I32: 0 | J32: 1 | K32: ✅
A33: 31 | B33: 2026-04-08 03:59:27 | C33: https://pedagiodigital-auto.com/atendimento/home.php | D33: phishing | E33: Typosquatting | F33: Phishing | G33: 1 | H33: 0 | I33: 0 | J33: 0 | K33: ✅ | L33: site can't be reached
A34: 32 | B34: 2026-04-08 03:59:41 | C34: http://sso-en-ca-netcoins-com-nav-azure.webflow.io/ | D34: phishing | E34: Mixed Content | F34: Aman | G34: 0 | H34: 0 | I34: 1 | J34: 0 | K34: ❌
A35: 33 | B35: 2026-04-08 03:59:51 | C35: https://ckoinsquayrelogin.webflow.io/ | D35: phishing | E35: Credential Harvesting | F35: Phishing | G35: 1 | H35: 0 | I35: 0 | J35: 0 | K35: ✅
A36: 34 | B36: 2026-04-08 03:59:56 | C36: http://www.instagram-clone-lime.vercel.app/ | D36: phishing | E36: Mixed Content | F36: Phishing | G36: 1 | H36: 0 | I36: 0 | J36: 0 | K36: ✅
A37: 35 | B37: 2026-04-08 04:00:03 | C37: https://kucologinn.webflow.io/ | D37: phishing | E37: Credential Harvesting | F37: Phishing | G37: 1 | H37: 0 | I37: 0 | J37: 0 | K37: ✅
A38: 36 | B38: 2026-04-08 04:00:09 | C38: http://www.netflix-clone-six-black.vercel.app/ | D38: phishing | E38: Mixed Content | F38: Phishing | G38: 1 | H38: 0 | I38: 0 | J38: 0 | K38: ✅
A39: 37 | B39: 2026-04-08 04:00:16 | C39: http://bafybeigbqwmxazxynaputje3qz5bp5im3grqzyqdzb3r3xb5uuzysijlt4.ipfs.infura-ipfs.io/ | D39: phishing | E39: Mixed Content | F39: Phishing | G39: 1 | H39: 0 | I39: 0 | J39: 0 | K39: ✅
A40: 38 | B40: 2026-04-08 04:00:25 | C40: http://bitmartloginx.webflow.io/ | D40: phishing | E40: Mixed Content | F40: Phishing | G40: 1 | H40: 0 | I40: 0 | J40: 0 | K40: ✅
A41: 39 | B41: 2026-04-08 04:00:30 | C41: https://kuocoinlognco.godaddysites.com/ | D41: phishing | E41: Typosquatting | F41: Phishing | G41: 1 | H41: 0 | I41: 0 | J41: 0 | K41: ✅
A42: 40 | B42: 2026-04-08 04:00:49 | C42: http://www.kuocoinlognco.godaddysites.com/ | D42: phishing | E42: Mixed Content | F42: Phishing | G42: 1 | H42: 0 | I42: 0 | J42: 0 | K42: ✅ | L42: connection iz not private
A43: 41 | B43: 2026-04-08 04:00:57 | C43: https://shopeeid0277.blogspot.com/ | D43: phishing | E43: Typosquatting | F43: Aman | G43: 0 | H43: 0 | I43: 1 | J43: 0 | K43: ❌
A44: 42 | B44: 2026-04-08 04:01:13 | C44: https://www.shopeeid0277.blogspot.com/ | D44: phishing | E44: Typosquatting | F44: Phishing | G44: 1 | H44: 0 | I44: 0 | J44: 0 | K44: ✅ | L44: connection is not private
A45: 43 | B45: 2026-04-08 04:01:17 | C45: https://verifyhub.agency-partner-manage.com/ | D45: phishing | E45: Credential Harvesting | F45: Phishing | G45: 1 | H45: 0 | I45: 0 | J45: 0 | K45: ✅
A46: 44 | B46: 2026-04-08 04:01:21 | C46: https://spotify-clone-sepia-nine.vercel.app/ | D46: phishing | E46: Typosquatting | F46: Phishing | G46: 1 | H46: 0 | I46: 0 | J46: 0 | K46: ✅
A47: 45 | B47: 2026-04-08 04:01:26 | C47: https://gemini.jerryfage.top/ | D47: phishing | E47: Suspicious TLDs | F47: Phishing | G47: 1 | H47: 0 | I47: 0 | J47: 0 | K47: ✅
A48: 46 | B48: 2026-04-08 04:01:30 | C48: https://www.elglobomalaga.es/ | D48: phishing | E48: Typosquatting | F48: Phishing | G48: 1 | H48: 0 | I48: 0 | J48: 0 | K48: ✅
A49: 47 | B49: 2026-04-08 04:01:34 | C49: https://site-aic91fv1h.godaddysites.com/ | D49: phishing | E49: Typosquatting | F49: Phishing | G49: 1 | H49: 0 | I49: 0 | J49: 0 | K49: ✅
A50: 48 | B50: 2026-04-08 04:01:49 | C50: http://www.site-aic91fv1h.godaddysites.com/ | D50: phishing | E50: Mixed Content | F50: Phishing | G50: 1 | H50: 0 | I50: 0 | J50: 0 | K50: ✅ | L50: connection is not private
A51: 49 | B51: 2026-04-08 04:02:04 | C51: https://www.gnigginnladgu.godaddysites.com/ | D51: phishing | E51: Typosquatting | F51: Phishing | G51: 1 | H51: 0 | I51: 0 | J51: 0 | K51: ✅ | L51: connection is not private
A52: 50 | B52: 2026-04-08 04:02:09 | C52: https://gnigginnladgu.godaddysites.com/ | D52: phishing | E52: Typosquatting | F52: Phishing | G52: 1 | H52: 0 | I52: 0 | J52: 0 | K52: ✅
A53: 51 | B53: 2026-04-08 04:02:13 | C53: https://ncloneapp.netlify.app/ | D53: phishing | E53: Typosquatting | F53: Phishing | G53: 1 | H53: 0 | I53: 0 | J53: 0 | K53: ✅
A54: 52 | B54: 2026-04-08 04:02:17 | C54: http://effulgent-phoenix-778ccd.netlify.app/ | D54: phishing | E54: Mixed Content | F54: Phishing | G54: 1 | H54: 0 | I54: 0 | J54: 0 | K54: ✅
A55: 53 | B55: 2026-04-08 04:02:24 | C55: https://www.robiox.com.py/users/358158342831/profile | D55: phishing | E55: Typosquatting | F55: Aman | G55: 0 | H55: 0 | I55: 1 | J55: 0 | K55: ❌
A56: 54 | B56: 2026-04-08 04:02:28 | C56: https://booking-clone-next-js.vercel.app/ | D56: phishing | E56: Typosquatting | F56: Phishing | G56: 1 | H56: 0 | I56: 0 | J56: 0 | K56: ✅
A57: 55 | B57: 2026-04-08 04:02:32 | C57: http://www.booking-clone-next-js.vercel.app/ | D57: phishing | E57: Mixed Content | F57: Phishing | G57: 1 | H57: 0 | I57: 0 | J57: 0 | K57: ✅
...

Sheet Lionic Qr Scanner
A1: LOG PENGUJIAN: LIONIC QR SCANNER
A2: No | B2: Waktu | C2: URL | D2: Label Aktual | E2: Kategori | F2: Hasil Scanner | G2: TP | H2: FP | I2: FN | J2: TN | K2: Benar? | L2: Catatan
A3: 1 | B3: 2026-04-08 03:40:19 | C3: https://ccunpacked.dev/ | D3: safe | E3: Live Safe (Tech News) | F3: Phishing | G3: 0 | H3: 1 | I3: 0 | J3: 0 | K3: ❌ | L3: unverified
A4: 2 | B4: 2026-04-08 03:40:26 | C4: https://home.cern/news/news/engineering/cern-levels-new-superconducting-karts | D4: safe | E4: Live Safe (Tech News) | F4: Aman | G4: 0 | H4: 0 | I4: 0 | J4: 1 | K4: ✅
A5: 3 | B5: 2026-04-08 03:40:31 | C5: https://www.science.org/content/article/neanderthals-survived-knife-s-edge-350-000-years | D5: safe | E5: Live Safe (Tech News) | F5: Aman | G5: 0 | H5: 0 | I5: 0 | J5: 1 | K5: ✅
A6: 4 | B6: 2026-04-08 03:40:38 | C6: https://blog.calif.io/p/mad-bugs-vim-vs-emacs-vs-claude | D6: safe | E6: Live Safe (Tech News) | F6: Phishing | G6: 0 | H6: 1 | I6: 0 | J6: 0 | K6: ❌ | L6: unverified
A7: 5 | B7: 2026-04-08 03:40:44 | C7: https://www.jeffgeerling.com/blog/2026/minidv-with-raspberry-pi-firewire-hat/ | D7: safe | E7: Live Safe (Tech News) | F7: Aman | G7: 0 | H7: 0 | I7: 0 | J7: 1 | K7: ✅
A8: 6 | B8: 2026-04-08 03:40:49 | C8: https://arxiv.org/abs/2602.04118 | D8: safe | E8: Live Safe (Tech News) | F8: Aman | G8: 0 | H8: 0 | I8: 0 | J8: 1 | K8: ✅
A9: 7 | B9: 2026-04-08 03:40:58 | C9: https://chrisseaton.com/truffleruby/ | D9: safe | E9: Live Safe (Tech News) | F9: Phishing | G9: 0 | H9: 1 | I9: 0 | J9: 0 | K9: ❌ | L9: unverified
A10: 8 | B10: 2026-04-08 03:41:06 | C10: https://prismml.com/ | D10: safe | E10: Live Safe (Tech News) | F10: Phishing | G10: 0 | H10: 1 | I10: 0 | J10: 0 | K10: ❌ | L10: unverified
A11: 9 | B11: 2026-04-08 03:41:14 | C11: https://scottlawsonbc.com/post/dot-system | D11: safe | E11: Live Safe (Tech News) | F11: Phishing | G11: 0 | H11: 1 | I11: 0 | J11: 0 | K11: ❌ | L11: unverified
A12: 10 | B12: 2026-04-08 03:41:21 | C12: https://github.com/yannick-cw/korb | D12: safe | E12: Live Safe (Tech News) | F12: Aman | G12: 0 | H12: 0 | I12: 0 | J12: 1 | K12: ✅
A13: 11 | B13: 2026-04-08 03:41:30 | C13: https://ministack.org/ | D13: safe | E13: Live Safe (Tech News) | F13: Phishing | G13: 0 | H13: 1 | I13: 0 | J13: 0 | K13: ❌ | L13: unverified
A14: 12 | B14: 2026-04-08 03:41:36 | C14: https://alex000kim.com/posts/2026-03-31-claude-code-source-leak/ | D14: safe | E14: Live Safe (Tech News) | F14: Phishing | G14: 0 | H14: 1 | I14: 0 | J14: 0 | K14: ❌ | L14: unverified
A15: 13 | B15: 2026-04-08 03:41:44 | C15: https://www.dbpro.app/blog/chess-in-pure-sql | D15: safe | E15: Live Safe (Tech News) | F15: Phishing | G15: 0 | H15: 1 | I15: 0 | J15: 0 | K15: ❌ | L15: unverified
A16: 14 | B16: 2026-04-08 03:41:49 | C16: https://www.cnbc.com/2026/03/31/openai-funding-round-ipo.html | D16: safe | E16: Live Safe (Tech News) | F16: Aman | G16: 0 | H16: 0 | I16: 0 | J16: 1 | K16: ✅
A17: 15 | B17: 2026-04-08 03:41:56 | C17: https://swiftrocks.com/digitizing-photos-from-the-1998-game-boy-camera | D17: safe | E17: Live Safe (Tech News) | F17: Phishing | G17: 0 | H17: 1 | I17: 0 | J17: 0 | K17: ❌ | L17: unverified
A18: 16 | B18: 2026-04-08 03:42:02 | C18: http://lughat.blogspot.com/2017/10/butterfly-collecting-history-of-insult.html | D18: safe | E18: Live Safe (Tech News) | F18: Aman | G18: 0 | H18: 0 | I18: 0 | J18: 1 | K18: ✅
A19: 17 | B19: 2026-04-08 03:42:06 | C19: https://www.geekbench.com/blog/2026/03/analyzing-geekbench-6-under-intels-bot/ | D19: safe | E19: Live Safe (Tech News) | F19: Aman | G19: 0 | H19: 0 | I19: 0 | J19: 1 | K19: ✅
A20: 18 | B20: 2026-04-08 03:42:10 | C20: https://github.com/danieldugas/HYPERHELL | D20: safe | E20: Live Safe (Tech News) | F20: Aman | G20: 0 | H20: 0 | I20: 0 | J20: 1 | K20: ✅
A21: 19 | B21: 2026-04-08 03:42:16 | C21: https://www.greptile.com/blog/ai-slopware-future | D21: safe | E21: Live Safe (Tech News) | F21: Phishing | G21: 0 | H21: 1 | I21: 0 | J21: 0 | K21: ❌ | L21: unverified
A22: 20 | B22: 2026-04-08 03:42:22 | C22: https://nautil.us/ordinary-lab-gloves-may-have-skewed-microplastic-data-1279386 | D22: safe | E22: Live Safe (Tech News) | F22: Aman | G22: 0 | H22: 0 | I22: 0 | J22: 1 | K22: ✅
A23: 21 | B23: 2026-04-08 03:42:31 | C23: https://solvespace.com/webver.pl | D23: safe | E23: Live Safe (Tech News) | F23: Phishing | G23: 0 | H23: 1 | I23: 0 | J23: 0 | K23: ❌ | L23: unverified
A24: 22 | B24: 2026-04-08 03:42:38 | C24: https://responsiblestatecraft.org/iran-strait-of-hormuz/ | D24: safe | E24: Live Safe (Tech News) | F24: Phishing | G24: 0 | H24: 1 | I24: 0 | J24: 0 | K24: ❌ | L24: unverified
A25: 23 | B25: 2026-04-08 03:42:47 | C25: https://hypha.pub/back-to-freebsd-part-2 | D25: safe | E25: Live Safe (Tech News) | F25: Phishing | G25: 0 | H25: 1 | I25: 0 | J25: 0 | K25: ❌ | L25: unverified
A26: 24 | B26: 2026-04-08 03:42:52 | C26: https://github.com/ericlewis/libpo32 | D26: safe | E26: Live Safe (Tech News) | F26: Aman | G26: 0 | H26: 0 | I26: 0 | J26: 1 | K26: ✅
A27: 25 | B27: 2026-04-08 03:42:57 | C27: https://cohere.com/blog/transcribe | D27: safe | E27: Live Safe (Tech News) | F27: Aman | G27: 0 | H27: 0 | I27: 0 | J27: 1 | K27: ✅
A28: 26 | B28: 2026-04-08 03:43:03 | C28: https://www.stepsecurity.io/blog/axios-compromised-on-npm-malicious-versions-drop-remote-access-trojan | D28: safe | E28: Live Safe (Tech News) | F28: Phishing | G28: 0 | H28: 1 | I28: 0 | J28: 0 | K28: ❌ | L28: unverified
A29: 27 | B29: 2026-04-08 03:43:08 | C29: https://github.com/timescale/pg_textsearch | D29: safe | E29: Live Safe (Tech News) | F29: Aman | G29: 0 | H29: 0 | I29: 0 | J29: 1 | K29: ✅
A30: 28 | B30: 2026-04-08 03:43:16 | C30: https://tech.stonecharioteer.com/posts/2026/tailscale-exit-nodes/ | D30: safe | E30: Live Safe (Tech News) | F30: Phishing | G30: 0 | H30: 1 | I30: 0 | J30: 0 | K30: ❌ | L30: unverified
A31: 29 | B31: 2026-04-08 03:43:23 | C31: https://news.future-shock.ai/the-weight-of-remembering/ | D31: safe | E31: Live Safe (Tech News) | F31: Phishing | G31: 0 | H31: 1 | I31: 0 | J31: 0 | K31: ❌ | L31: unverified
A32: 30 | B32: 2026-04-08 03:43:28 | C32: https://www.os2museum.com/wp/learn-something-old-every-day-part-xviii-how-does-fpu-detection-work/ | D32: safe | E32: Live Safe (Tech News) | F32: Aman | G32: 0 | H32: 0 | I32: 0 | J32: 1 | K32: ✅
A33: 31 | B33: 2026-04-08 03:43:36 | C33: https://pedagiodigital-auto.com/atendimento/home.php | D33: phishing | E33: Typosquatting | F33: Phishing | G33: 1 | H33: 0 | I33: 0 | J33: 0 | K33: ✅
A34: 32 | B34: 2026-04-08 03:43:42 | C34: http://sso-en-ca-netcoins-com-nav-azure.webflow.io/ | D34: phishing | E34: Mixed Content | F34: Phishing | G34: 1 | H34: 0 | I34: 0 | J34: 0 | K34: ✅
A35: 33 | B35: 2026-04-08 03:43:46 | C35: https://ckoinsquayrelogin.webflow.io/ | D35: phishing | E35: Credential Harvesting | F35: Phishing | G35: 1 | H35: 0 | I35: 0 | J35: 0 | K35: ✅
A36: 34 | B36: 2026-04-08 03:43:50 | C36: http://www.instagram-clone-lime.vercel.app/ | D36: phishing | E36: Mixed Content | F36: Phishing | G36: 1 | H36: 0 | I36: 0 | J36: 0 | K36: ✅
A37: 35 | B37: 2026-04-08 03:43:53 | C37: https://kucologinn.webflow.io/ | D37: phishing | E37: Credential Harvesting | F37: Phishing | G37: 1 | H37: 0 | I37: 0 | J37: 0 | K37: ✅
A38: 36 | B38: 2026-04-08 03:43:56 | C38: http://www.netflix-clone-six-black.vercel.app/ | D38: phishing | E38: Mixed Content | F38: Phishing | G38: 1 | H38: 0 | I38: 0 | J38: 0 | K38: ✅
A39: 37 | B39: 2026-04-08 03:44:00 | C39: http://bafybeigbqwmxazxynaputje3qz5bp5im3grqzyqdzb3r3xb5uuzysijlt4.ipfs.infura-ipfs.io/ | D39: phishing | E39: Mixed Content | F39: Phishing | G39: 1 | H39: 0 | I39: 0 | J39: 0 | K39: ✅
A40: 38 | B40: 2026-04-08 03:44:03 | C40: http://bitmartloginx.webflow.io/ | D40: phishing | E40: Mixed Content | F40: Phishing | G40: 1 | H40: 0 | I40: 0 | J40: 0 | K40: ✅
...

Sheet QR Scan Shield
A1: LOG PENGUJIAN: QR SCAN SHIELD
A2: No | B2: Waktu | C2: URL | D2: Label Aktual | E2: Kategori | F2: Hasil Scanner | G2: TP | H2: FP | I2: FN | J2: TN | K2: Benar? | L2: Catatan

Sheet Ringkasan
A1: RINGKASAN PERBANDINGAN SEMUA SCANNER
A2: Scanner | B2: TP | C2: FP | D2: FN | E2: TN | F2: Precision | G2: Recall | H2: F1-Score
A3: iOS Camera (Built-in) | B3: =IFERROR(SUMIF('iOS Camera (Built-in)'!D$3:D$1000,"phishing",'iOS Camera (Built-in)'!G$3:G$1000),0) | C3: =IFERROR(SUMIF('iOS Camera (Built-in)'!D$3:D$1000,"safe",'iOS Camera (Built-in)'!H$3:H$1000),0) | D3: =IFERROR(SUMIF('iOS Camera (Built-in)'!D$3:D$1000,"phishing",'iOS Camera (Built-in)'!I$3:I$1000),0) | E3: =IFERROR(SUMIF('iOS Camera (Built-in)'!D$3:D$1000,"safe",'iOS Camera (Built-in)'!J$3:J$1000),0) | F3: =IFERROR(B3/(B3+C3),0) | G3: =IFERROR(B3/(B3+D3),0) | H3: =IFERROR(2*F3*G3/(F3+G3),0)
A4: Samsung Camera (Built-in) | B4: =IFERROR(SUMIF('Samsung Camera (Built-in)'!D$3:D$1000,"phishing",'Samsung Camera (Built-in)'!G$3:G$1000),0) | C4: =IFERROR(SUMIF('Samsung Camera (Built-in)'!D$3:D$1000,"safe",'Samsung Camera (Built-in)'!H$3:H$1000),0) | D4: =IFERROR(SUMIF('Samsung Camera (Built-in)'!D$3:D$1000,"phishing",'Samsung Camera (Built-in)'!I$3:I$1000),0) | E4: =IFERROR(SUMIF('Samsung Camera (Built-in)'!D$3:D$1000,"safe",'Samsung Camera (Built-in)'!J$3:J$1000),0) | F4: =IFERROR(B4/(B4+C4),0) | G4: =IFERROR(B4/(B4+D4),0) | H4: =IFERROR(2*F4*G4/(F4+G4),0)
A5: Redmi Camera (Built-in) | B5: =IFERROR(SUMIF('Redmi Camera (Built-in)'!D$3:D$1000,"phishing",'Redmi Camera (Built-in)'!G$3:G$1000),0) | C5: =IFERROR(SUMIF('Redmi Camera (Built-in)'!D$3:D$1000,"safe",'Redmi Camera (Built-in)'!H$3:H$1000),0) | D5: =IFERROR(SUMIF('Redmi Camera (Built-in)'!D$3:D$1000,"phishing",'Redmi Camera (Built-in)'!I$3:I$1000),0) | E5: =IFERROR(SUMIF('Redmi Camera (Built-in)'!D$3:D$1000,"safe",'Redmi Camera (Built-in)'!J$3:J$1000),0) | F5: =IFERROR(B5/(B5+C5),0) | G5: =IFERROR(B5/(B5+D5),0) | H5: =IFERROR(2*F5*G5/(F5+G5),0)
A6: Google Lens | B6: =IFERROR(SUMIF('Google Lens'!D$3:D$1000,"phishing",'Google Lens'!G$3:G$1000),0) | C6: =IFERROR(SUMIF('Google Lens'!D$3:D$1000,"safe",'Google Lens'!H$3:H$1000),0) | D6: =IFERROR(SUMIF('Google Lens'!D$3:D$1000,"phishing",'Google Lens'!I$3:I$1000),0) | E6: =IFERROR(SUMIF('Google Lens'!D$3:D$1000,"safe",'Google Lens'!J$3:J$1000),0) | F6: =IFERROR(B6/(B6+C6),0) | G6: =IFERROR(B6/(B6+D6),0) | H6: =IFERROR(2*F6*G6/(F6+G6),0)
A7: Lionic Qr Scanner | B7: =IFERROR(SUMIF('Lionic Qr Scanner'!D$3:D$1000,"phishing",'Lionic Qr Scanner'!G$3:G$1000),0) | C7: =IFERROR(SUMIF('Lionic Qr Scanner'!D$3:D$1000,"safe",'Lionic Qr Scanner'!H$3:H$1000),0) | D7: =IFERROR(SUMIF('Lionic Qr Scanner'!D$3:D$1000,"phishing",'Lionic Qr Scanner'!I$3:I$1000),0) | E7: =IFERROR(SUMIF('Lionic Qr Scanner'!D$3:D$1000,"safe",'Lionic Qr Scanner'!J$3:J$1000),0) | F7: =IFERROR(B7/(B7+C7),0) | G7: =IFERROR(B7/(B7+D7),0) | H7: =IFERROR(2*F7*G7/(F7+G7),0)
A8: QR Scan Shield | B8: =IFERROR(SUMIF('QR Scan Shield'!D$3:D$1000,"phishing",'QR Scan Shield'!G$3:G$1000),0) | C8: =IFERROR(SUMIF('QR Scan Shield'!D$3:D$1000,"safe",'QR Scan Shield'!H$3:H$1000),0) | D8: =IFERROR(SUMIF('QR Scan Shield'!D$3:D$1000,"phishing",'QR Scan Shield'!I$3:I$1000),0) | E8: =IFERROR(SUMIF('QR Scan Shield'!D$3:D$1000,"safe",'QR Scan Shield'!J$3:J$1000),0) | F8: =IFERROR(B8/(B8+C8),0) | G8: =IFERROR(B8/(B8+D8),0) | H8: =IFERROR(2*F8*G8/(F8+G8),0)
